<mujoco model="lever_model">
    <compiler angle="radian" />
    <worldbody>
    <body>
    <body name="object">    
    <body name="link_1" pos="0 0 0.05">
        <geom name="base" type="box" size=".1 .1 .05" pos="0 0 0" rgba="0 0 1 1" group="0"/>
        <geom name="s1" type="box" size=".025 .075 .025" pos=" .04 0 .075" rgba="0 0 1 1" group="0"/>
        <geom name="s2" type="box" size=".025 .075 .025" pos="-.04 0 .075" rgba="0 0 1 1" group="0"/>
    </body>
    
    <body name="lever" pos="0 0 .315">
          <inertial pos="0 0 0" mass="1." diaginertia="8.80012e-0 8.80012e-0 8.80012e-0"/>
          <geom name="lever" rgba="0.3 1 0.3 1" size=".015 .2 .015" type="cylinder" margin="0.001"
                contype="1" conaffinity="1" condim="3" friction="1 0.1 0.002" group="0" 
            />
          <joint type="hinge" range="-.5 1.45" axis="1 0 0" name="joint_1" pos="0 0 -.2" damping="1" armature="0"/>
          <site name="handle" pos="0 0 .3" size="0.02" rgba="0 0 1 1" />                    
        </body>
    </body>
    <site name="bottom_site" pos="0 0 -0.3" rgba="0 0 0 0" size="0.005"/>
    <site name="top_site" pos="0 0 0.3" rgba="0 0 0 0" size="0.005"/>
    <site name="horizontal_radius_site" pos="0.3 0 0" rgba="0 0 0 0" size="0.1"/>
    </body>
    </worldbody>
</mujoco>
