<mujoco model="wheel_model">
    <compiler angle="radian" />
    <worldbody>
    <body>
    <body name="object">    
    <body name="base" pos="0 0 -.05">
        <geom name="base" type="box" size=".1 .1 .05" pos="0 0 0" rgba="0 0 1 1" group="0"/>
    </body>
    
    <body name="link_1" pos="0 .15 .025">
        <geom name="wheel_base" rgba="0.3 1 0.3 1" size=".015 .075 .015" pos="0 -.075 0" euler="-1.57 0 0" type="cylinder" margin="0.001"
                group="0" 
        />

        <geom name="wheel" rgba="1 0 0 1" size=".015 .075 .015"  pos="0 .075 0" euler="-1.57 0 0" type="cylinder" margin="0.001"
                group="0" 
        />
        
        <joint name="hinge" type="hinge" pos="0 0 0" axis="0 0 1" damping="0.1" limited="true" range="-.5 .5" />
        <site name="handle" pos="-.02 0.15 0" size="0.02" rgba="0 0 1 1" />  
        </body>
    </body>
    <site name="bottom_site" pos="0 0 -0.3" rgba="0 0 0 0" size="0.005"/>
    <site name="top_site" pos="0 0 0.3" rgba="0 0 0 0" size="0.005"/>
    <site name="horizontal_radius_site" pos="0.3 0 0" rgba="0 0 0 0" size="0.1"/>
    </body>
    </worldbody>
</mujoco>